Workbook

Sheet README
A1: Monthly Portfolio Pack
A2: Owner: Group Finance, Reporting Team
A3: Data as of: 31 August 2026
A5: Monthly process
A6: 1. Receive the three DWH extracts by email (balance cube, originations, applications).
A7: 2. Paste each extract below the last row of its Data_ tab. Copy the Product line formula down on Data_Balances.
A8: 3. Add the new month end rates from the Treasury email to the FX table on Lookups.
A9: 4. On each country tab, copy the last row down one row and enter the new month end date in column A.
A10: 5. Extend the Summary tab by one row. Check the chart picks it up.
A11: 6. Paste Summary as values into the board pack slides.
A13: Tabs
A14: Summary: group KPIs for the board pack.
... A23: v14 Summary chart re-pointed after row insert.

Sheet Summary
A1: Group portfolio KPIs (EUR)
A4: Month end | B4: Portfolio balance (EUR) | C4: New accounts | D4: New originations (EUR) | E4: 30+ DPD rate | F4: 90+ DPD rate | G4: Approval rate | H4: Avg balance per customer (EUR)
A5: 45565 | B5: =PL!D5+CZ!D5+RO!D5 | C5: =PL!E5+CZ!E5+RO!E5 | D5: =PL!G5+CZ!G5+RO!G5 | E5: =IFERROR((PL!I5*PL!D5+CZ!I5*CZ!D5+RO!I5*RO!D5)/B5,0) | F5: =IFERROR((PL!K5*PL!D5+CZ!K5*CZ!D5+RO!K5*RO!D5)/B5,0) | G5: =IFERROR((PL!M5+CZ!M5+RO!M5)/(PL!L5+CZ!L5+RO!L5),0) | H5: =IFERROR(B5/(PL!O5+CZ!O5+RO!O5),0)
A6: 45596 | B6: =PL!D6+CZ!D6+RO!D6 | C6: =PL!E6+CZ!E6+RO!E6 | D6: =PL!G6+CZ!G6+RO!G6 | E6: =IFERROR((PL!I6*PL!D6+CZ!I6*CZ!D6+RO!I6*RO!D6)/B6,0) | F6: =IFERROR((PL!K6*PL!D6+CZ!K6*CZ!D6+RO!K6*RO!D6)/B6,0) | G6: =IFERROR((PL!M6+CZ!M6+RO!M6)/(PL!L6+CZ!L6+RO!L6),0) | H6: =IFERROR(B6/(PL!O6+CZ!O6+RO!O6),0)
A7: 45626 | B7: =PL!D7+CZ!D7+RO!D7 | C7: =PL!E7+CZ!E7+RO!E7 | D7: =PL!G7+CZ!G7+RO!G7 | E7: =IFERROR((PL!I7*PL!D7+CZ!I7*CZ!D7+RO!I7*RO!D7)/B7,0) | F7: =IFERROR((PL!K7*PL!D7+CZ!K7*CZ!D7+RO!K7*RO!D7)/B7,0) | G7: =IFERROR((PL!M7+CZ!M7+RO!M7)/(PL!L7+CZ!L7+RO!L7),0) | H7: =IFERROR(B7/(PL!O7+CZ!O7+RO!O7),0)
A8: 45657 | B8: =PL!D8+CZ!D8+RO!D8 | C8: =PL!E8+CZ!E8+RO!E8 | D8: =PL!G8+CZ!G8+RO!G8 | E8: =IFERROR((PL!I8*PL!D8+CZ!I8*CZ!D8+RO!I8*RO!D8)/B8,0) | F8: =IFERROR((PL!K8*PL!D8+CZ!K8*CZ!D8+RO!K8*RO!D8)/B8,0) | G8: =IFERROR((PL!M8+CZ!M8+RO!M8)/(PL!L8+CZ!L8+RO!L8),0) | H8: =IFERROR(B8/(PL!O8+CZ!O8+RO!O8),0)
A9: 45688 | B9: =PL!D9+CZ!D9+RO!D9 | C9: =PL!E9+CZ!E9+RO!E9 | D9: =PL!G9+CZ!G9+RO!G9 | E9: =IFERROR((PL!I9*PL!D9+CZ!I9*CZ!D9+RO!I9*RO!D9)/B9,0) | F9: =IFERROR((PL!K9*PL!D9+CZ!K9*CZ!D9+RO!K9*RO!D9)/B9,0) | G9: =IFERROR((PL!M9+CZ!M9+RO!M9)/(PL!L9+CZ!L9+RO!L9),0) | H9: =IFERROR(B9/(PL!O9+CZ!O9+RO!O9),0)
A10: 45716 | B10: =PL!D10+CZ!D10+RO!D10 | C10: =PL!E10+CZ!E10+RO!E10 | D10: =PL!G10+CZ!G10+RO!G10 | E10: =IFERROR((PL!I10*PL!D10+CZ!I10*CZ!D10+RO!I10*RO!D10)/B10,0) | F10: =IFERROR((PL!K10*PL!D10+CZ!K10*CZ!D10+RO!K10*RO!D10)/B10,0) | G10: =IFERROR((PL!M10+CZ!M10+RO!M10)/(PL!L10+CZ!L10+RO!L10),0) | H10: =IFERROR(B10/(PL!O10+CZ!O10+RO!O10),0)
A11: 45747 | B11: =PL!D11+CZ!D11+RO!D11 | C11: =PL!E11+CZ!E11+RO!E11 | D11: =PL!G11+CZ!G11+RO!G11 | E11: =IFERROR((PL!I11*PL!D11+CZ!I11*CZ!D11+RO!I11*RO!D11)/B11,0) | F11: =IFERROR((PL!K11*PL!D11+CZ!K11*CZ!D11+RO!K11*RO!D11)/B11,0) | G11: =IFERROR((PL!M11+CZ!M11+RO!M11)/(PL!L11+CZ!L11+RO!L11),0) | H11: =IFERROR(B11/(PL!O11+CZ!O11+RO!O11),0)
A12: 45777 | B12: =PL!D12+CZ!D12+RO!D12 | C12: =PL!E12+CZ!E12+RO!E12 | D12: =PL!G12+CZ!G12+RO!G12 | E12: =IFERROR((PL!I12*PL!D12+CZ!I12*CZ!D12+RO!I12*RO!D12)/B12,0) | F12: =IFERROR((PL!K12*PL!D12+CZ!K12*CZ!D12+RO!K12*RO!D12)/B12,0) | G12: =IFERROR((PL!M12+CZ!M12+RO!M12)/(PL!L12+CZ!L12+RO!L12),0) | H12: =IFERROR(B12/(PL!O12+CZ!O12+RO!O12),0)
A13: 45808 | B13: =PL!D13+CZ!D13+RO!D13 | C13: =PL!E13+CZ!E13+RO!E13 | D13: =PL!G13+CZ!G13+RO!G13 | E13: =IFERROR((PL!I13*PL!D13+CZ!I13*CZ!D13+RO!I13*RO!D13)/B13,0) | F13: =IFERROR((PL!K13*PL!D13+CZ!K13*CZ!D13+RO!K13*RO!D13)/B13,0) | G13: =IFERROR((PL!M13+CZ!M13+RO!M13)/(PL!L13+CZ!L13+RO!L13),0) | H13: =IFERROR(B13/(PL!O13+CZ!O13+RO!O13),0)
A14: 45838 | B14: =PL!D14+CZ!D14+RO!D14 | C14: =PL!E14+CZ!E14+RO!E14 | D14: =PL!G14+CZ!G14+RO!G14 | E14: =IFERROR((PL!I14*PL!D14+CZ!I14*CZ!D14+RO!I14*RO!D14)/B14,0) | F14: =IFERROR((PL!K14*PL!D14+CZ!K14*CZ!D14+RO!K14*RO!D14)/B14,0) | G14: =IFERROR((PL!M14+CZ!M14+RO!M14)/(PL!L14+CZ!L14+RO!L14),0) | H14: =IFERROR(B14/(PL!O14+CZ!O14+RO!O14),0)
A15: 45869 | B15: =PL!D15+CZ!D15+RO!D15 | C15: =PL!E15+CZ!E15+RO!E15 | D15: =PL!G15+CZ!G15+RO!G15 | E15: =IFERROR((PL!I15*PL!D15+CZ!I15*CZ!D15+RO!I15*RO!D15)/B15,0) | F15: =IFERROR((PL!K15*PL!D15+CZ!K15*CZ!D15+RO!K15*RO!D15)/B15,0) | G15: =IFERROR((PL!M15+CZ!M15+RO!M15)/(PL!L15+CZ!L15+RO!L15),0) | H15: =IFERROR(B15/(PL!O15+CZ!O15+RO!O15),0)
A16: 45900 | B16: =PL!D16+CZ!D16+RO!D16 | C16: =PL!E16+CZ!E16+RO!E16 | D16: =PL!G16+CZ!G16+RO!G16 | E16: =IFERROR((PL!I16*PL!D16+CZ!I16*CZ!D16+RO!I16*RO!D16)/B16,0) | F16: =IFERROR((PL!K16*PL!D16+CZ!K16*CZ!D16+RO!K16*RO!D16)/B16,0) | G16: =IFERROR((PL!M16+CZ!M16+RO!M16)/(PL!L16+CZ!L16+RO!L16),0) | H16: =IFERROR(B16/(PL!O16+CZ!O16+RO!O16),0)
... A28: 46265 | B28: =PL!D28+CZ!D28+RO!D28 | C28: =PL!E28+CZ!E28+RO!E28 | D28: =PL!G28+CZ!G28+RO!G28 | E28: =IFERROR((PL!I28*PL!D28+CZ!I28*CZ!D28+RO!I28*RO!D28)/B28,0) | F28: =IFERROR((PL!K28*PL!D28+CZ!K28*CZ!D28+RO!K28*RO!D28)/B28,0) | G28: =IFERROR((PL!M28+CZ!M28+RO!M28)/(PL!L28+CZ!L28+RO!L28),0) | H28: =IFERROR(B28/(PL!O28+CZ!O28+RO!O28),0)

Sheet PL
A1: Country | B1: PL | C1: Poland
A2: Currency | B2: PLN
A4: Month end | B4: Portfolio balance (local) | C4: FX rate to EUR | D4: Portfolio balance (EUR) | E4: New accounts | F4: New originations (local) | G4: New originations (EUR) | H4: Balance 30+ DPD (local) | I4: 30+ DPD rate | J4: Balance 90+ DPD (local) | K4: 90+ DPD rate | L4: Applications received | M4: Applications approved | N4: Approval rate | O4: Active accounts | P4: Avg balance per customer (EUR)
A5: 45565 | B5: =SUMIFS(Data_Balances!$G:$G,Data_Balances!$A:$A,$A5,Data_Balances!$B:$B,$B$1,Data_Balances!$H:$H,"Personal Loans")+SUMIFS(Data_Balances!$G:$G,Data_Balances!$A:$A,$A5,Data_Balances!$B:$B,$B$1,Data_Balances!$C:$C,"CC*") | C5: =INDEX(Lookups!$F$3:$H$26,MATCH($A5,Lookups!$E$3:$E$26,0),MATCH($B$2,Lookups!$F$2:$H$2,0)) | D5: =B5*C5 | E5: =SUMIFS(Data_Originations!$D:$D,Data_Originations!$A:$A,$A5,Data_Originations!$B:$B,$B$1) | F5: =SUMIFS(Data_Originations!$E:$E,Data_Originations!$A:$A,$A5,Data_Originations!$B:$B,$B$1) | G5: =F5*C5 | H5: =SUMIFS(Data_Balances!$G:$G,Data_Balances!$A:$A,EOMONTH($A5,-1),Data_Balances!$B:$B,$B$1,Data_Balances!$E:$E,">=30") | I5: =IFERROR(H5/SUMIFS(Data_Balances!$G:$G,Data_Balances!$A:$A,$A5,Data_Balances!$B:$B,$B$1),0) | J5: =SUMIFS(Data_Balances!$G:$G,Data_Balances!$A:$A,$A5,Data_Balances!$B:$B,$B$1,Data_Balances!$E:$E,">=90") | K5: =IFERROR(J5/SUMIFS(Data_Balances!$G:$G,Data_Balances!$A:$A,$A5,Data_Balances!$B:$B,$B$1),0) | L5: =SUMIFS(Data_Applications!$D:$D,Data_Applications!$A:$A,$A5,Data_Applications!$B:$B,$B$1) | M5: =SUMIFS(Data_Applications!$E:$E,Data_Applications!$A:$A,$A5,Data_Applications!$B:$B,$B$1) | N5: =IFERROR(M5/L5,0) | O5: =SUMIFS(Data_Balances!$F:$F,Data_Balances!$A:$A,$A5,Data_Balances!$B:$B,$B$1) | P5: =IFERROR(D5/O5,0)
A6: 45596 | B6: =SUMIFS(Data_Balances!$G:$G,Data_Balances!$A:$A,$A6,Data_Balances!$B:$B,$B$1,Data_Balances!$H:$H,"Personal Loans")+SUMIFS(Data_Balances!$G:$G,Data_Balances!$A:$A,$A6,Data_Balances!$B:$B,$B$1,Data_Balances!$C:$C,"CC*") | C6: =INDEX(Lookups!$F$3:$H$26,MATCH($A6,Lookups!$E$3:$E$26,0),MATCH($B$2,Lookups!$F$2:$H$2,0)) | D6: =B6*C6 | E6: =SUMIFS(Data_Originations!$D:$D,Data_Originations!$A:$A,$A6,Data_Originations!$B:$B,$B$1) | F6: =SUMIFS(Data_Originations!$E:$E,Data_Originations!$A:$A,$A6,Data_Originations!$B:$B,$B$1) | G6: =F6*C6 | H6: =SUMIFS(Data_Balances!$G:$G,Data_Balances!$A:$A,EOMONTH($A6,-1),Data_Balances!$B:$B,$B$1,Data_Balances!$E:$E,">=30") | I6: =IFERROR(H6/SUMIFS(Data_Balances!$G:$G,Data_Balances!$A:$A,$A6,Data_Balances!$B:$B,$B$1),0) | J6: =SUMIFS(Data_Balances!$G:$G,Data_Balances!$A:$A,$A6,Data_Balances!$B:$B,$B$1,Data_Balances!$E:$E,">=90") | K6: =IFERROR(J6/SUMIFS(Data_Balances!$G:$G,Data_Balances!$A:$A,$A6,Data_Balances!$B:$B,$B$1),0) | L6: =SUMIFS(Data_Applications!$D:$D,Data_Applications!$A:$A,$A6,Data_Applications!$B:$B,$B$1) | M6: =SUMIFS(Data_Applications!$E:$E,Data_Applications!$A:$A,$A6,Data_Applications!$B:$B,$B$1) | N6: =IFERROR(M6/L6,0) | O6: =SUMIFS(Data_Balances!$F:$F,Data_Balances!$A:$A,$A6,Data_Balances!$B:$B,$B$1) | P6: =IFERROR(D6/O6,0)
A7: 45626 | B7: =SUMIFS(Data_Balances!$G:$G,Data_Balances!$A:$A,$A7,Data_Balances!$B:$B,$B$1,Data_Balances!$H:$H,"Personal Loans")+SUMIFS(Data_Balances!$G:$G,Data_Balances!$A:$A,$A7,Data_Balances!$B:$B,$B$1,Data_Balances!$C:$C,"CC*") | C7: =INDEX(Lookups!$F$3:$H$26,MATCH($A7,Lookups!$E$3:$E$26,0),MATCH($B$2,Lookups!$F$2:$H$2,0)) | D7: =B7*C7 | E7: =SUMIFS(Data_Originations!$D:$D,Data_Originations!$A:$A,$A7,Data_Originations!$B:$B,$B$1) | F7: =SUMIFS(Data_Originations!$E:$E,Data_Originations!$A:$A,$A7,Data_Originations!$B:$B,$B$1) | G7: =F7*C7 | H7: =SUMIFS(Data_Balances!$G:$G,Data_Balances!$A:$A,EOMONTH($A7,-1),Data_Balances!$B:$B,$B$1,Data_Balances!$E:$E,">=30") | I7: =IFERROR(H7/SUMIFS(Data_Balances!$G:$G,Data_Balances!$A:$A,$A7,Data_Balances!$B:$B,$B$1),0) | J7: =SUMIFS(Data_Balances!$G:$G,Data_Balances!$A:$A,$A7,Data_Balances!$B:$B,$B$1,Data_Balances!$E:$E,">=90") | K7: =IFERROR(J7/SUMIFS(Data_Balances!$G:$G,Data_Balances!$A:$A,$A7,Data_Balances!$B:$B,$B$1),0) | L7: =SUMIFS(Data_Applications!$D:$D,Data_Applications!$A:$A,$A7,Data_Applications!$B:$B,$B$1) | M7: =SUMIFS(Data_Applications!$E:$E,Data_Applications!$A:$A,$A7,Data_Applications!$B:$B,$B$1) | N7: =IFERROR(M7/L7,0) | O7: =SUMIFS(Data_Balances!$F:$F,Data_Balances!$A:$A,$A7,Data_Balances!$B:$B,$B$1) | P7: =IFERROR(D7/O7,0)
A8: 45657 | B8: =SUMIFS(Data_Balances!$G:$G,Data_Balances!$A:$A,$A8,Data_Balances!$B:$B,$B$1,Data_Balances!$H:$H,"Personal Loans")+SUMIFS(Data_Balances!$G:$G,Data_Balances!$A:$A,$A8,Data_Balances!$B:$B,$B$1,Data_Balances!$C:$C,"CC*") | C8: =INDEX(Lookups!$F$3:$H$26,MATCH($A8,Lookups!$E$3:$E$26,0),MATCH($B$2,Lookups!$F$2:$H$2,0)) | D8: =B8*C8 | E8: =SUMIFS(Data_Originations!$D:$D,Data_Originations!$A:$A,$A8,Data_Originations!$B:$B,$B$1) | F8: =SUMIFS(Data_Originations!$E:$E,Data_Originations!$A:$A,$A8,Data_Originations!$B:$B,$B$1) | G8: =F8*C8 | H8: =SUMIFS(Data_Balances!$G:$G,Data_Balances!$A:$A,EOMONTH($A8,-1),Data_Balances!$B:$B,$B$1,Data_Balances!$E:$E,">=30") | I8: =IFERROR(H8/SUMIFS(Data_Balances!$G:$G,Data_Balances!$A:$A,$A8,Data_Balances!$B:$B,$B$1),0) | J8: =SUMIFS(Data_Balances!$G:$G,Data_Balances!$A:$A,$A8,Data_Balances!$B:$B,$B$1,Data_Balances!$E:$E,">=90") | K8: =IFERROR(J8/SUMIFS(Data_Balances!$G:$G,Data_Balances!$A:$A,$A8,Data_Balances!$B:$B,$B$1),0) | L8: =SUMIFS(Data_Applications!$D:$D,Data_Applications!$A:$A,$A8,Data_Applications!$B:$B,$B$1) | M8: =SUMIFS(Data_Applications!$E:$E,Data_Applications!$A:$A,$A8,Data_Applications!$B:$B,$B$1) | N8: =IFERROR(M8/L8,0) | O8: =SUMIFS(Data_Balances!$F:$F,Data_Balances!$A:$A,$A8,Data_Balances!$B:$B,$B$1) | P8: =IFERROR(D8/O8,0)
A9: 45688 | B9: =SUMIFS(Data_Balances!$G:$G,Data_Balances!$A:$A,$A9,Data_Balances!$B:$B,$B$1,Data_Balances!$H:$H,"Personal Loans")+SUMIFS(Data_Balances!$G:$G,Data_Balances!$A:$A,$A9,Data_Balances!$B:$B,$B$1,Data_Balances!$C:$C,"CC*") | C9: =INDEX(Lookups!$F$3:$H$26,MATCH($A9,Lookups!$E$3:$E$26,0),MATCH($B$2,Lookups!$F$2:$H$2,0)) | D9: =B9*C9 | E9: =SUMIFS(Data_Originations!$D:$D,Data_Originations!$A:$A,$A9,Data_Originations!$B:$B,$B$1) | F9: =SUMIFS(Data_Originations!$E:$E,Data_Originations!$A:$A,$A9,Data_Originations!$B:$B,$B$1) | G9: =F9*C9 | H9: =SUMIFS(Data_Balances!$G:$G,Data_Balances!$A:$A,EOMONTH($A9,-1),Data_Balances!$B:$B,$B$1,Data_Balances!$E:$E,">=30") | I9: =IFERROR(H9/SUMIFS(Data_Balances!$G:$G,Data_Balances!$A:$A,$A9,Data_Balances!$B:$B,$B$1),0) | J9: =SUMIFS(Data_Balances!$G:$G,Data_Balances!$A:$A,$A9,Data_Balances!$B:$B,$B$1,Data_Balances!$E:$E,">=90") | K9: =IFERROR(J9/SUMIFS(Data_Balances!$G:$G,Data_Balances!$A:$A,$A9,Data_Balances!$B:$B,$B$1),0) | L9: =SUMIFS(Data_Applications!$D:$D,Data_Applications!$A:$A,$A9,Data_Applications!$B:$B,$B$1) | M9: =SUMIFS(Data_Applications!$E:$E,Data_Applications!$A:$A,$A9,Data_Applications!$B:$B,$B$1) | N9: =IFERROR(M9/L9,0) | O9: =SUMIFS(Data_Balances!$F:$F,Data_Balances!$A:$A,$A9,Data_Balances!$B:$B,$B$1) | P9: =IFERROR(D9/O9,0)
A10: 45716 | B10: =SUMIFS(Data_Balances!$G:$G,Data_Balances!$A:$A,$A10,Data_Balances!$B:$B,$B$1,Data_Balances!$H:$H,"Personal Loans")+SUMIFS(Data_Balances!$G:$G,Data_Balances!$A:$A,$A10,Data_Balances!$B:$B,$B$1,Data_Balances!$C:$C,"CC*") | C10: =INDEX(Lookups!$F$3:$H$26,MATCH($A10,Lookups!$E$3:$E$26,0),MATCH($B$2,Lookups!$F$2:$H$2,0)) | D10: =B10*C10 | E10: =SUMIFS(Data_Originations!$D:$D,Data_Originations!$A:$A,$A10,Data_Originations!$B:$B,$B$1) | F10: =SUMIFS(Data_Originations!$E:$E,Data_Originations!$A:$A,$A10,Data_Originations!$B:$B,$B$1) | G10: =F10*C10 | H10: =SUMIFS(Data_Balances!$G:$G,Data_Balances!$A:$A,EOMONTH($A10,-1),Data_Balances!$B:$B,$B$1,Data_Balances!$E:$E,">=30") | I10: =IFERROR(H10/SUMIFS(Data_Balances!$G:$G,Data_Balances!$A:$A,$A10,Data_Balances!$B:$B,$B$1),0) | J10: =SUMIFS(Data_Balances!$G:$G,Data_Balances!$A:$A,$A10,Data_Balances!$B:$B,$B$1,Data_Balances!$E:$E,">=90") | K10: =IFERROR(J10/SUMIFS(Data_Balances!$G:$G,Data_Balances!$A:$A,$A10,Data_Balances!$B:$B,$B$1),0) | L10: =SUMIFS(Data_Applications!$D:$D,Data_Applications!$A:$A,$A10,Data_Applications!$B:$B,$B$1) | M10: =SUMIFS(Data_Applications!$E:$E,Data_Applications!$A:$A,$A10,Data_Applications!$B:$B,$B$1) | N10: =IFERROR(M10/L10,0) | O10: =SUMIFS(Data_Balances!$F:$F,Data_Balances!$A:$A,$A10,Data_Balances!$B:$B,$B$1) | P10: =IFERROR(D10/O10,0)
A11: 45747 | B11: =SUMIFS(Data_Balances!$G:$G,Data_Balances!$A:$A,$A11,Data_Balances!$B:$B,$B$1,Data_Balances!$H:$H,"Personal Loans")+SUMIFS(Data_Balances!$G:$G,Data_Balances!$A:$A,$A11,Data_Balances!$B:$B,$B$1,Data_Balances!$C:$C,"CC*") | C11: =INDEX(Lookups!$F$3:$H$26,MATCH($A11,Lookups!$E$3:$E$26,0),MATCH($B$2,Lookups!$F$2:$H$2,0)) | D11: =B11*C11 | E11: =SUMIFS(Data_Originations!$D:$D,Data_Originations!$A:$A,$A11,Data_Originations!$B:$B,$B$1) | F11: =SUMIFS(Data_Originations!$E:$E,Data_Originations!$A:$A,$A11,Data_Originations!$B:$B,$B$1) | G11: =F11*C11 | H11: =SUMIFS(Data_Balances!$G:$G,Data_Balances!$A:$A,EOMONTH($A11,-1),Data_Balances!$B:$B,$B$1,Data_Balances!$E:$E,">=30") | I11: =IFERROR(H11/SUMIFS(Data_Balances!$G:$G,Data_Balances!$A:$A,$A11,Data_Balances!$B:$B,$B$1),0) | J11: =SUMIFS(Data_Balances!$G:$G,Data_Balances!$A:$A,$A11,Data_Balances!$B:$B,$B$1,Data_Balances!$E:$E,">=90") | K11: =IFERROR(J11/SUMIFS(Data_Balances!$G:$G,Data_Balances!$A:$A,$A11,Data_Balances!$B:$B,$B$1),0) | L11: =SUMIFS(Data_Applications!$D:$D,Data_Applications!$A:$A,$A11,Data_Applications!$B:$B,$B$1) | M11: =SUMIFS(Data_Applications!$E:$E,Data_Applications!$A:$A,$A11,Data_Applications!$B:$B,$B$1) | N11: =IFERROR(M11/L11,0) | O11: =SUMIFS(Data_Balances!$F:$F,Data_Balances!$A:$A,$A11,Data_Balances!$B:$B,$B$1) | P11: =IFERROR(D11/O11,0)
A12: 45777 | B12: =SUMIFS(Data_Balances!$G:$G,Data_Balances!$A:$A,$A12,Data_Balances!$B:$B,$B$1,Data_Balances!$H:$H,"Personal Loans")+SUMIFS(Data_Balances!$G:$G,Data_Balances!$A:$A,$A12,Data_Balances!$B:$B,$B$1,Data_Balances!$C:$C,"CC*") | C12: =INDEX(Lookups!$F$3:$H$26,MATCH($A12,Lookups!$E$3:$E$26,0),MATCH($B$2,Lookups!$F$2:$H$2,0)) | D12: =B12*C12 | E12: =SUMIFS(Data_Originations!$D:$D,Data_Originations!$A:$A,$A12,Data_Originations!$B:$B,$B$1) | F12: =SUMIFS(Data_Originations!$E:$E,Data_Originations!$A:$A,$A12,Data_Originations!$B:$B,$B$1) | G12: =F12*C12 | H12: =SUMIFS(Data_Balances!$G:$G,Data_Balances!$A:$A,EOMONTH($A12,-1),Data_Balances!$B:$B,$B$1,Data_Balances!$E:$E,">=30") | I12: =IFERROR(H12/SUMIFS(Data_Balances!$G:$G,Data_Balances!$A:$A,$A12,Data_Balances!$B:$B,$B$1),0) | J12: =SUMIFS(Data_Balances!$G:$G,Data_Balances!$A:$A,$A12,Data_Balances!$B:$B,$B$1,Data_Balances!$E:$E,">=90") | K12: =IFERROR(J12/SUMIFS(Data_Balances!$G:$G,Data_Balances!$A:$A,$A12,Data_Balances!$B:$B,$B$1),0) | L12: =SUMIFS(Data_Applications!$D:$D,Data_Applications!$A:$A,$A12,Data_Applications!$B:$B,$B$1) | M12: =SUMIFS(Data_Applications!$E:$E,Data_Applications!$A:$A,$A12,Data_Applications!$B:$B,$B$1) | N12: =IFERROR(M12/L12,0) | O12: =SUMIFS(Data_Balances!$F:$F,Data_Balances!$A:$A,$A12,Data_Balances!$B:$B,$B$1) | P12: =IFERROR(D12/O12,0)
A13: 45808 | B13: =SUMIFS(Data_Balances!$G:$G,Data_Balances!$A:$A,$A13,Data_Balances!$B:$B,$B$1,Data_Balances!$H:$H,"Personal Loans")+SUMIFS(Data_Balances!$G:$G,Data_Balances!$A:$A,$A13,Data_Balances!$B:$B,$B$1,Data_Balances!$C:$C,"CC*") | C13: =INDEX(Lookups!$F$3:$H$26,MATCH($A13,Lookups!$E$3:$E$26,0),MATCH($B$2,Lookups!$F$2:$H$2,0)) | D13: =B13*C13 | E13: =SUMIFS(Data_Originations!$D:$D,Data_Originations!$A:$A,$A13,Data_Originations!$B:$B,$B$1) | F13: =SUMIFS(Data_Originations!$E:$E,Data_Originations!$A:$A,$A13,Data_Originations!$B:$B,$B$1) | G13: =F13*C13 | H13: =SUMIFS(Data_Balances!$G:$G,Data_Balances!$A:$A,EOMONTH($A13,-1),Data_Balances!$B:$B,$B$1,Data_Balances!$E:$E,">=30") | I13: =IFERROR(H13/SUMIFS(Data_Balances!$G:$G,Data_Balances!$A:$A,$A13,Data_Balances!$B:$B,$B$1),0) | J13: =SUMIFS(Data_Balances!$G:$G,Data_Balances!$A:$A,$A13,Data_Balances!$B:$B,$B$1,Data_Balances!$E:$E,">=90") | K13: =IFERROR(J13/SUMIFS(Data_Balances!$G:$G,Data_Balances!$A:$A,$A13,Data_Balances!$B:$B,$B$1),0) | L13: =SUMIFS(Data_Applications!$D:$D,Data_Applications!$A:$A,$A13,Data_Applications!$B:$B,$B$1) | M13: =SUMIFS(Data_Applications!$E:$E,Data_Applications!$A:$A,$A13,Data_Applications!$B:$B,$B$1) | N13: =IFERROR(M13/L13,0) | O13: =SUMIFS(Data_Balances!$F:$F,Data_Balances!$A:$A,$A13,Data_Balances!$B:$B,$B$1) | P13: =IFERROR(D13/O13,0)
A14: 45838 | B14: =SUMIFS(Data_Balances!$G:$G,Data_Balances!$A:$A,$A14,Data_Balances!$B:$B,$B$1,Data_Balances!$H:$H,"Personal Loans")+SUMIFS(Data_Balances!$G:$G,Data_Balances!$A:$A,$A14,Data_Balances!$B:$B,$B$1,Data_Balances!$C:$C,"CC*") | C14: =INDEX(Lookups!$F$3:$H$26,MATCH($A14,Lookups!$E$3:$E$26,0),MATCH($B$2,Lookups!$F$2:$H$2,0)) | D14: =B14*C14 | E14: =SUMIFS(Data_Originations!$D:$D,Data_Originations!$A:$A,$A14,Data_Originations!$B:$B,$B$1) | F14: =SUMIFS(Data_Originations!$E:$E,Data_Originations!$A:$A,$A14,Data_Originations!$B:$B,$B$1) | G14: =F14*C14 | H14: =SUMIFS(Data_Balances!$G:$G,Data_Balances!$A:$A,EOMONTH($A14,-1),Data_Balances!$B:$B,$B$1,Data_Balances!$E:$E,">=30") | I14: =IFERROR(H14/SUMIFS(Data_Balances!$G:$G,Data_Balances!$A:$A,$A14,Data_Balances!$B:$B,$B$1),0) | J14: =SUMIFS(Data_Balances!$G:$G,Data_Balances!$A:$A,$A14,Data_Balances!$B:$B,$B$1,Data_Balances!$E:$E,">=90") | K14: =IFERROR(J14/SUMIFS(Data_Balances!$G:$G,Data_Balances!$A:$A,$A14,Data_Balances!$B:$B,$B$1),0) | L14: =SUMIFS(Data_Applications!$D:$D,Data_Applications!$A:$A,$A14,Data_Applications!$B:$B,$B$1) | M14: =SUMIFS(Data_Applications!$E:$E,Data_Applications!$A:$A,$A14,Data_Applications!$B:$B,$B$1) | N14: =IFERROR(M14/L14,0) | O14: =SUMIFS(Data_Balances!$F:$F,Data_Balances!$A:$A,$A14,Data_Balances!$B:$B,$B$1) | P14: =IFERROR(D14/O14,0)
A15: 45869 | B15: =SUMIFS(Data_Balances!$G:$G,Data_Balances!$A:$A,$A15,Data_Balances!$B:$B,$B$1,Data_Balances!$H:$H,"Personal Loans")+SUMIFS(Data_Balances!$G:$G,Data_Balances!$A:$A,$A15,Data_Balances!$B:$B,$B$1,Data_Balances!$C:$C,"CC*") | C15: =INDEX(Lookups!$F$3:$H$26,MATCH($A15,Lookups!$E$3:$E$26,0),MATCH($B$2,Lookups!$F$2:$H$2,0)) | D15: =B15*C15 | E15: =SUMIFS(Data_Originations!$D:$D,Data_Originations!$A:$A,$A15,Data_Originations!$B:$B,$B$1) | F15: =SUMIFS(Data_Originations!$E:$E,Data_Originations!$A:$A,$A15,Data_Originations!$B:$B,$B$1) | G15: =F15*C15 | H15: =SUMIFS(Data_Balances!$G:$G,Data_Balances!$A:$A,EOMONTH($A15,-1),Data_Balances!$B:$B,$B$1,Data_Balances!$E:$E,">=30") | I15: =IFERROR(H15/SUMIFS(Data_Balances!$G:$G,Data_Balances!$A:$A,$A15,Data_Balances!$B:$B,$B$1),0) | J15: =SUMIFS(Data_Balances!$G:$G,Data_Balances!$A:$A,$A15,Data_Balances!$B:$B,$B$1,Data_Balances!$E:$E,">=90") | K15: =IFERROR(J15/SUMIFS(Data_Balances!$G:$G,Data_Balances!$A:$A,$A15,Data_Balances!$B:$B,$B$1),0) | L15: =SUMIFS(Data_Applications!$D:$D,Data_Applications!$A:$A,$A15,Data_Applications!$B:$B,$B$1) | M15: =SUMIFS(Data_Applications!$E:$E,Data_Applications!$A:$A,$A15,Data_Applications!$B:$B,$B$1) | N15: =IFERROR(M15/L15,0) | O15: =SUMIFS(Data_Balances!$F:$F,Data_Balances!$A:$A,$A15,Data_Balances!$B:$B,$B$1) | P15: =IFERROR(D15/O15,0)
A16: 45900 | B16: =SUMIFS(Data_Balances!$G:$G,Data_Balances!$A:$A,$A16,Data_Balances!$B:$B,$B$1,Data_Balances!$H:$H,"Personal Loans")+SUMIFS(Data_Balances!$G:$G,Data_Balances!$A:$A,$A16,Data_Balances!$B:$B,$B$1,Data_Balances!$C:$C,"CC*") | C16: =INDEX(Lookups!$F$3:$H$26,MATCH($A16,Lookups!$E$3:$E$26,0),MATCH($B$2,Lookups!$F$2:$H$2,0)) | D16: =B16*C16 | E16: =SUMIFS(Data_Originations!$D:$D,Data_Originations!$A:$A,$A16,Data_Originations!$B:$B,$B$1) | F16: =SUMIFS(Data_Originations!$E:$E,Data_Originations!$A:$A,$A16,Data_Originations!$B:$B,$B$1) | G16: =F16*C16 | H16: =SUMIFS(Data_Balances!$G:$G,Data_Balances!$A:$A,EOMONTH($A16,-1),Data_Balances!$B:$B,$B$1,Data_Balances!$E:$E,">=30") | I16: =IFERROR(H16/SUMIFS(Data_Balances!$G:$G,Data_Balances!$A:$A,$A16,Data_Balances!$B:$B,$B$1),0) | J16: =SUMIFS(Data_Balances!$G:$G,Data_Balances!$A:$A,$A16,Data_Balances!$B:$B,$B$1,Data_Balances!$E:$E,">=90") | K16: =IFERROR(J16/SUMIFS(Data_Balances!$G:$G,Data_Balances!$A:$A,$A16,Data_Balances!$B:$B,$B$1),0) | L16: =SUMIFS(Data_Applications!$D:$D,Data_Applications!$A:$A,$A16,Data_Applications!$B:$B,$B$1) | M16: =SUMIFS(Data_Applications!$E:$E,Data_Applications!$A:$A,$A16,Data_Applications!$B:$B,$B$1) | N16: =IFERROR(M16/L16,0) | O16: =SUMIFS(Data_Balances!$F:$F,Data_Balances!$A:$A,$A16,Data_Balances!$B:$B,$B$1) | P16: =IFERROR(D16/O16,0)
... A28: 46265 | B28: =SUMIFS(Data_Balances!$G:$G,Data_Balances!$A:$A,$A28,Data_Balances!$B:$B,$B$1,Data_Balances!$H:$H,"Personal Loans")+SUMIFS(Data_Balances!$G:$G,Data_Balances!$A:$A,$A28,Data_Balances!$B:$B,$B$1,Data_Balances!$C:$C,"CC*") | C28: =INDEX(Lookups!$F$3:$H$26,MATCH($A28,Lookups!$E$3:$E$26,0),MATCH($B$2,Lookups!$F$2:$H$2,0)) | D28: =B28*C28 | E28: =SUMIFS(Data_Originations!$D:$D,Data_Originations!$A:$A,$A28,Data_Originations!$B:$B,$B$1) | F28: =SUMIFS(Data_Originations!$E:$E,Data_Originations!$A:$A,$A28,Data_Originations!$B:$B,$B$1) | G28: =F28*C28 | H28: =SUMIFS(Data_Balances!$G:$G,Data_Balances!$A:$A,EOMONTH($A28,-1),Data_Balances!$B:$B,$B$1,Data_Balances!$E:$E,">=30") | I28: =IFERROR(H28/SUMIFS(Data_Balances!$G:$G,Data_Balances!$A:$A,$A28,Data_Balances!$B:$B,$B$1),0) | J28: =SUMIFS(Data_Balances!$G:$G,Data_Balances!$A:$A,$A28,Data_Balances!$B:$B,$B$1,Data_Balances!$E:$E,">=90") | K28: =IFERROR(J28/SUMIFS(Data_Balances!$G:$G,Data_Balances!$A:$A,$A28,Data_Balances!$B:$B,$B$1),0) | L28: =SUMIFS(Data_Applications!$D:$D,Data_Applications!$A:$A,$A28,Data_Applications!$B:$B,$B$1) | M28: =SUMIFS(Data_Applications!$E:$E,Data_Applications!$A:$A,$A28,Data_Applications!$B:$B,$B$1) | N28: =IFERROR(M28/L28,0) | O28: =SUMIFS(Data_Balances!$F:$F,Data_Balances!$A:$A,$A28,Data_Balances!$B:$B,$B$1) | P28: =IFERROR(D28/O28,0)

Sheet CZ
A1: Country | B1: CZ | C1: Czech Republic
A2: Currency | B2: CZK
A4: Month end | B4: Portfolio balance (local) | C4: FX rate to EUR | D4: Portfolio balance (EUR) | E4: New accounts | F4: New originations (local) | G4: New originations (EUR) | H4: Balance 30+ DPD (local) | I4: 30+ DPD rate | J4: Balance 90+ DPD (local) | K4: 90+ DPD rate | L4: Applications received | M4: Applications approved | N4: Approval rate | O4: Active accounts | P4: Avg balance per customer (EUR)
A5: 45565 | B5: =SUMIFS(Data_Balances!$G:$G,Data_Balances!$A:$A,$A5,Data_Balances!$B:$B,$B$1,Data_Balances!$H:$H,"Personal Loans")+SUMIFS(Data_Balances!$G:$G,Data_Balances!$A:$A,$A5,Data_Balances!$B:$B,$B$1,Data_Balances!$C:$C,"CC*") | C5: =INDEX(Lookups!$F$3:$H$26,MATCH($A5,Lookups!$E$3:$E$26,0),MATCH($B$2,Lookups!$F$2:$H$2,0)) | D5: =B5*C5 | E5: =SUMIFS(Data_Originations!$D:$D,Data_Originations!$A:$A,$A5,Data_Originations!$B:$B,$B$1) | F5: =SUMIFS(Data_Originations!$E:$E,Data_Originations!$A:$A,$A5,Data_Originations!$B:$B,$B$1) | G5: =F5*C5 | H5: =SUMIFS(Data_Balances!$G:$G,Data_Balances!$A:$A,EOMONTH($A5,-1),Data_Balances!$B:$B,$B$1,Data_Balances!$E:$E,">=30") | I5: =IFERROR(H5/SUMIFS(Data_Balances!$G:$G,Data_Balances!$A:$A,$A5,Data_Balances!$B:$B,$B$1),0) | J5: =SUMIFS(Data_Balances!$G:$G,Data_Balances!$A:$A,$A5,Data_Balances!$B:$B,$B$1,Data_Balances!$E:$E,">=90") | K5: =IFERROR(J5/SUMIFS(Data_Balances!$G:$G,Data_Balances!$A:$A,$A5,Data_Balances!$B:$B,$B$1),0) | L5: =SUMIFS(Data_Applications!$D:$D,Data_Applications!$A:$A,$A5,Data_Applications!$B:$B,$B$1) | M5: =SUMIFS(Data_Applications!$E:$E,Data_Applications!$A:$A,$A5,Data_Applications!$B:$B,$B$1) | N5: =IFERROR(M5/L5,0) | O5: =SUMIFS(Data_Balances!$F:$F,Data_Balances!$A:$A,$A5,Data_Balances!$B:$B,$B$1) | P5: =IFERROR(D5/O5,0)
A6: 45596 | B6: =SUMIFS(Data_Balances!$G:$G,Data_Balances!$A:$A,$A6,Data_Balances!$B:$B,$B$1,Data_Balances!$H:$H,"Personal Loans")+SUMIFS(Data_Balances!$G:$G,Data_Balances!$A:$A,$A6,Data_Balances!$B:$B,$B$1,Data_Balances!$C:$C,"CC*") | C6: =INDEX(Lookups!$F$3:$H$26,MATCH($A6,Lookups!$E$3:$E$26,0),MATCH($B$2,Lookups!$F$2:$H$2,0)) | D6: =B6*C6 | E6: =SUMIFS(Data_Originations!$D:$D,Data_Originations!$A:$A,$A6,Data_Originations!$B:$B,$B$1) | F6: =SUMIFS(Data_Originations!$E:$E,Data_Originations!$A:$A,$A6,Data_Originations!$B:$B,$B$1) | G6: =F6*C6 | H6: =SUMIFS(Data_Balances!$G:$G,Data_Balances!$A:$A,EOMONTH($A6,-1),Data_Balances!$B:$B,$B$1,Data_Balances!$E:$E,">=30") | I6: =IFERROR(H6/SUMIFS(Data_Balances!$G:$G,Data_Balances!$A:$A,$A6,Data_Balances!$B:$B,$B$1),0) | J6: =SUMIFS(Data_Balances!$G:$G,Data_Balances!$A:$A,$A6,Data_Balances!$B:$B,$B$1,Data_Balances!$E:$E,">=90") | K6: =IFERROR(J6/SUMIFS(Data_Balances!$G:$G,Data_Balances!$A:$A,$A6,Data_Balances!$B:$B,$B$1),0) | L6: =SUMIFS(Data_Applications!$D:$D,Data_Applications!$A:$A,$A6,Data_Applications!$B:$B,$B$1) | M6: =SUMIFS(Data_Applications!$E:$E,Data_Applications!$A:$A,$A6,Data_Applications!$B:$B,$B$1) | N6: =IFERROR(M6/L6,0) | O6: =SUMIFS(Data_Balances!$F:$F,Data_Balances!$A:$A,$A6,Data_Balances!$B:$B,$B$1) | P6: =IFERROR(D6/O6,0)
A7: 45626 | B7: =SUMIFS(Data_Balances!$G:$G,Data_Balances!$A:$A,$A7,Data_Balances!$B:$B,$B$1,Data_Balances!$H:$H,"Personal Loans")+SUMIFS(Data_Balances!$G:$G,Data_Balances!$A:$A,$A7,Data_Balances!$B:$B,$B$1,Data_Balances!$C:$C,"CC*") | C7: =INDEX(Lookups!$F$3:$H$26,MATCH($A7,Lookups!$E$3:$E$26,0),MATCH($B$2,Lookups!$F$2:$H$2,0)) | D7: =B7*C7 | E7: =SUMIFS(Data_Originations!$D:$D,Data_Originations!$A:$A,$A7,Data_Originations!$B:$B,$B$1) | F7: =SUMIFS(Data_Originations!$E:$E,Data_Originations!$A:$A,$A7,Data_Originations!$B:$B,$B$1) | G7: =F7*C7 | H7: =SUMIFS(Data_Balances!$G:$G,Data_Balances!$A:$A,EOMONTH($A7,-1),Data_Balances!$B:$B,$B$1,Data_Balances!$E:$E,">=30") | I7: =IFERROR(H7/SUMIFS(Data_Balances!$G:$G,Data_Balances!$A:$A,$A7,Data_Balances!$B:$B,$B$1),0) | J7: =SUMIFS(Data_Balances!$G:$G,Data_Balances!$A:$A,$A7,Data_Balances!$B:$B,$B$1,Data_Balances!$E:$E,">=90") | K7: =IFERROR(J7/SUMIFS(Data_Balances!$G:$G,Data_Balances!$A:$A,$A7,Data_Balances!$B:$B,$B$1),0) | L7: =SUMIFS(Data_Applications!$D:$D,Data_Applications!$A:$A,$A7,Data_Applications!$B:$B,$B$1) | M7: =SUMIFS(Data_Applications!$E:$E,Data_Applications!$A:$A,$A7,Data_Applications!$B:$B,$B$1) | N7: =IFERROR(M7/L7,0) | O7: =SUMIFS(Data_Balances!$F:$F,Data_Balances!$A:$A,$A7,Data_Balances!$B:$B,$B$1) | P7: =IFERROR(D7/O7,0)
A8: 45657 | B8: =SUMIFS(Data_Balances!$G:$G,Data_Balances!$A:$A,$A8,Data_Balances!$B:$B,$B$1,Data_Balances!$H:$H,"Personal Loans")+SUMIFS(Data_Balances!$G:$G,Data_Balances!$A:$A,$A8,Data_Balances!$B:$B,$B$1,Data_Balances!$C:$C,"CC*") | C8: =INDEX(Lookups!$F$3:$H$26,MATCH($A8,Lookups!$E$3:$E$26,0),MATCH($B$2,Lookups!$F$2:$H$2,0)) | D8: =B8*C8 | E8: =SUMIFS(Data_Originations!$D:$D,Data_Originations!$A:$A,$A8,Data_Originations!$B:$B,$B$1) | F8: =SUMIFS(Data_Originations!$E:$E,Data_Originations!$A:$A,$A8,Data_Originations!$B:$B,$B$1) | G8: =F8*C8 | H8: =SUMIFS(Data_Balances!$G:$G,Data_Balances!$A:$A,EOMONTH($A8,-1),Data_Balances!$B:$B,$B$1,Data_Balances!$E:$E,">=30") | I8: =IFERROR(H8/SUMIFS(Data_Balances!$G:$G,Data_Balances!$A:$A,$A8,Data_Balances!$B:$B,$B$1),0) | J8: =SUMIFS(Data_Balances!$G:$G,Data_Balances!$A:$A,$A8,Data_Balances!$B:$B,$B$1,Data_Balances!$E:$E,">=90") | K8: =IFERROR(J8/SUMIFS(Data_Balances!$G:$G,Data_Balances!$A:$A,$A8,Data_Balances!$B:$B,$B$1),0) | L8: =SUMIFS(Data_Applications!$D:$D,Data_Applications!$A:$A,$A8,Data_Applications!$B:$B,$B$1) | M8: =SUMIFS(Data_Applications!$E:$E,Data_Applications!$A:$A,$A8,Data_Applications!$B:$B,$B$1) | N8: =IFERROR(M8/L8,0) | O8: =SUMIFS(Data_Balances!$F:$F,Data_Balances!$A:$A,$A8,Data_Balances!$B:$B,$B$1) | P8: =IFERROR(D8/O8,0)
A9: 45688 | B9: =SUMIFS(Data_Balances!$G:$G,Data_Balances!$A:$A,$A9,Data_Balances!$B:$B,$B$1,Data_Balances!$H:$H,"Personal Loans")+SUMIFS(Data_Balances!$G:$G,Data_Balances!$A:$A,$A9,Data_Balances!$B:$B,$B$1,Data_Balances!$C:$C,"CC*") | C9: =INDEX(Lookups!$F$3:$H$26,MATCH($A9,Lookups!$E$3:$E$26,0),MATCH($B$2,Lookups!$F$2:$H$2,0)) | D9: =B9*C9 | E9: =SUMIFS(Data_Originations!$D:$D,Data_Originations!$A:$A,$A9,Data_Originations!$B:$B,$B$1) | F9: =SUMIFS(Data_Originations!$E:$E,Data_Originations!$A:$A,$A9,Data_Originations!$B:$B,$B$1) | G9: =F9*C9 | H9: =SUMIFS(Data_Balances!$G:$G,Data_Balances!$A:$A,EOMONTH($A9,-1),Data_Balances!$B:$B,$B$1,Data_Balances!$E:$E,">=30") | I9: =IFERROR(H9/SUMIFS(Data_Balances!$G:$G,Data_Balances!$A:$A,$A9,Data_Balances!$B:$B,$B$1),0) | J9: =SUMIFS(Data_Balances!$G:$G,Data_Balances!$A:$A,$A9,Data_Balances!$B:$B,$B$1,Data_Balances!$E:$E,">=90") | K9: =IFERROR(J9/SUMIFS(Data_Balances!$G:$G,Data_Balances!$A:$A,$A9,Data_Balances!$B:$B,$B$1),0) | L9: =SUMIFS(Data_Applications!$D:$D,Data_Applications!$A:$A,$A9,Data_Applications!$B:$B,$B$1) | M9: =SUMIFS(Data_Applications!$E:$E,Data_Applications!$A:$A,$A9,Data_Applications!$B:$B,$B$1) | N9: =IFERROR(M9/L9,0) | O9: =SUMIFS(Data_Balances!$F:$F,Data_Balances!$A:$A,$A9,Data_Balances!$B:$B,$B$1) | P9: =IFERROR(D9/O9,0)
A10: 45716 | B10: =SUMIFS(Data_Balances!$G:$G,Data_Balances!$A:$A,$A10,Data_Balances!$B:$B,$B$1,Data_Balances!$H:$H,"Personal Loans")+SUMIFS(Data_Balances!$G:$G,Data_Balances!$A:$A,$A10,Data_Balances!$B:$B,$B$1,Data_Balances!$C:$C,"CC*") | C10: =INDEX(Lookups!$F$3:$H$26,MATCH($A10,Lookups!$E$3:$E$26,0),MATCH($B$2,Lookups!$F$2:$H$2,0)) | D10: =B10*C10 | E10: =SUMIFS(Data_Originations!$D:$D,Data_Originations!$A:$A,$A10,Data_Originations!$B:$B,$B$1) | F10: =SUMIFS(Data_Originations!$E:$E,Data_Originations!$A:$A,$A10,Data_Originations!$B:$B,$B$1) | G10: =F10*C10 | H10: =SUMIFS(Data_Balances!$G:$G,Data_Balances!$A:$A,EOMONTH($A10,-1),Data_Balances!$B:$B,$B$1,Data_Balances!$E:$E,">=30") | I10: =IFERROR(H10/SUMIFS(Data_Balances!$G:$G,Data_Balances!$A:$A,$A10,Data_Balances!$B:$B,$B$1),0) | J10: =SUMIFS(Data_Balances!$G:$G,Data_Balances!$A:$A,$A10,Data_Balances!$B:$B,$B$1,Data_Balances!$E:$E,">=90") | K10: =IFERROR(J10/SUMIFS(Data_Balances!$G:$G,Data_Balances!$A:$A,$A10,Data_Balances!$B:$B,$B$1),0) | L10: =SUMIFS(Data_Applications!$D:$D,Data_Applications!$A:$A,$A10,Data_Applications!$B:$B,$B$1) | M10: =SUMIFS(Data_Applications!$E:$E,Data_Applications!$A:$A,$A10,Data_Applications!$B:$B,$B$1) | N10: =IFERROR(M10/L10,0) | O10: =SUMIFS(Data_Balances!$F:$F,Data_Balances!$A:$A,$A10,Data_Balances!$B:$B,$B$1) | P10: =IFERROR(D10/O10,0)
A11: 45747 | B11: =SUMIFS(Data_Balances!$G:$G,Data_Balances!$A:$A,$A11,Data_Balances!$B:$B,$B$1,Data_Balances!$H:$H,"Personal Loans")+SUMIFS(Data_Balances!$G:$G,Data_Balances!$A:$A,$A11,Data_Balances!$B:$B,$B$1,Data_Balances!$C:$C,"CC*") | C11: =INDEX(Lookups!$F$3:$H$26,MATCH($A11,Lookups!$E$3:$E$26,0),MATCH($B$2,Lookups!$F$2:$H$2,0)) | D11: =B11*C11 | E11: =SUMIFS(Data_Originations!$D:$D,Data_Originations!$A:$A,$A11,Data_Originations!$B:$B,$B$1) | F11: =SUMIFS(Data_Originations!$E:$E,Data_Originations!$A:$A,$A11,Data_Originations!$B:$B,$B$1) | G11: =F11*C11 | H11: =SUMIFS(Data_Balances!$G:$G,Data_Balances!$A:$A,EOMONTH($A11,-1),Data_Balances!$B:$B,$B$1,Data_Balances!$E:$E,">=30") | I11: =IFERROR(H11/SUMIFS(Data_Balances!$G:$G,Data_Balances!$A:$A,$A11,Data_Balances!$B:$B,$B$1),0) | J11: =SUMIFS(Data_Balances!$G:$G,Data_Balances!$A:$A,$A11,Data_Balances!$B:$B,$B$1,Data_Balances!$E:$E,">=90") | K11: =IFERROR(J11/SUMIFS(Data_Balances!$G:$G,Data_Balances!$A:$A,$A11,Data_Balances!$B:$B,$B$1),0) | L11: =SUMIFS(Data_Applications!$D:$D,Data_Applications!$A:$A,$A11,Data_Applications!$B:$B,$B$1) | M11: =SUMIFS(Data_Applications!$E:$E,Data_Applications!$A:$A,$A11,Data_Applications!$B:$B,$B$1) | N11: =IFERROR(M11/L11,0) | O11: =SUMIFS(Data_Balances!$F:$F,Data_Balances!$A:$A,$A11,Data_Balances!$B:$B,$B$1) | P11: =IFERROR(D11/O11,0)
A12: 45777 | B12: =SUMIFS(Data_Balances!$G:$G,Data_Balances!$A:$A,$A12,Data_Balances!$B:$B,$B$1,Data_Balances!$H:$H,"Personal Loans")+SUMIFS(Data_Balances!$G:$G,Data_Balances!$A:$A,$A12,Data_Balances!$B:$B,$B$1,Data_Balances!$C:$C,"CC*") | C12: =INDEX(Lookups!$F$3:$H$26,MATCH($A12,Lookups!$E$3:$E$26,0),MATCH($B$2,Lookups!$F$2:$H$2,0)) | D12: =B12*C12 | E12: =SUMIFS(Data_Originations!$D:$D,Data_Originations!$A:$A,$A12,Data_Originations!$B:$B,$B$1) | F12: =SUMIFS(Data_Originations!$E:$E,Data_Originations!$A:$A,$A12,Data_Originations!$B:$B,$B$1) | G12: =F12*C12 | H12: =SUMIFS(Data_Balances!$G:$G,Data_Balances!$A:$A,EOMONTH($A12,-1),Data_Balances!$B:$B,$B$1,Data_Balances!$E:$E,">=30") | I12: =IFERROR(H12/SUMIFS(Data_Balances!$G:$G,Data_Balances!$A:$A,$A12,Data_Balances!$B:$B,$B$1),0) | J12: =SUMIFS(Data_Balances!$G:$G,Data_Balances!$A:$A,$A12,Data_Balances!$B:$B,$B$1,Data_Balances!$E:$E,">=90") | K12: =IFERROR(J12/SUMIFS(Data_Balances!$G:$G,Data_Balances!$A:$A,$A12,Data_Balances!$B:$B,$B$1),0) | L12: =SUMIFS(Data_Applications!$D:$D,Data_Applications!$A:$A,$A12,Data_Applications!$B:$B,$B$1) | M12: =SUMIFS(Data_Applications!$E:$E,Data_Applications!$A:$A,$A12,Data_Applications!$B:$B,$B$1) | N12: =IFERROR(M12/L12,0) | O12: =SUMIFS(Data_Balances!$F:$F,Data_Balances!$A:$A,$A12,Data_Balances!$B:$B,$B$1) | P12: =IFERROR(D12/O12,0)
A13: 45808 | B13: =SUMIFS(Data_Balances!$G:$G,Data_Balances!$A:$A,$A13,Data_Balances!$B:$B,$B$1,Data_Balances!$H:$H,"Personal Loans")+SUMIFS(Data_Balances!$G:$G,Data_Balances!$A:$A,$A13,Data_Balances!$B:$B,$B$1,Data_Balances!$C:$C,"CC*") | C13: =INDEX(Lookups!$F$3:$H$26,MATCH($A13,Lookups!$E$3:$E$26,0),MATCH($B$2,Lookups!$F$2:$H$2,0)) | D13: =B13*C13 | E13: =SUMIFS(Data_Originations!$D:$D,Data_Originations!$A:$A,$A13,Data_Originations!$B:$B,$B$1) | F13: =SUMIFS(Data_Originations!$E:$E,Data_Originations!$A:$A,$A13,Data_Originations!$B:$B,$B$1) | G13: =F13*C13 | H13: =SUMIFS(Data_Balances!$G:$G,Data_Balances!$A:$A,EOMONTH($A13,-1),Data_Balances!$B:$B,$B$1,Data_Balances!$E:$E,">=30") | I13: =IFERROR(H13/SUMIFS(Data_Balances!$G:$G,Data_Balances!$A:$A,$A13,Data_Balances!$B:$B,$B$1),0) | J13: =SUMIFS(Data_Balances!$G:$G,Data_Balances!$A:$A,$A13,Data_Balances!$B:$B,$B$1,Data_Balances!$E:$E,">=90") | K13: =IFERROR(J13/SUMIFS(Data_Balances!$G:$G,Data_Balances!$A:$A,$A13,Data_Balances!$B:$B,$B$1),0) | L13: =SUMIFS(Data_Applications!$D:$D,Data_Applications!$A:$A,$A13,Data_Applications!$B:$B,$B$1) | M13: =SUMIFS(Data_Applications!$E:$E,Data_Applications!$A:$A,$A13,Data_Applications!$B:$B,$B$1) | N13: =IFERROR(M13/L13,0) | O13: =SUMIFS(Data_Balances!$F:$F,Data_Balances!$A:$A,$A13,Data_Balances!$B:$B,$B$1) | P13: =IFERROR(D13/O13,0)
A14: 45838 | B14: =SUMIFS(Data_Balances!$G:$G,Data_Balances!$A:$A,$A14,Data_Balances!$B:$B,$B$1,Data_Balances!$H:$H,"Personal Loans")+SUMIFS(Data_Balances!$G:$G,Data_Balances!$A:$A,$A14,Data_Balances!$B:$B,$B$1,Data_Balances!$C:$C,"CC*") | C14: =INDEX(Lookups!$F$3:$H$26,MATCH($A14,Lookups!$E$3:$E$26,0),MATCH($B$2,Lookups!$F$2:$H$2,0)) | D14: =B14*C14 | E14: =SUMIFS(Data_Originations!$D:$D,Data_Originations!$A:$A,$A14,Data_Originations!$B:$B,$B$1) | F14: =SUMIFS(Data_Originations!$E:$E,Data_Originations!$A:$A,$A14,Data_Originations!$B:$B,$B$1) | G14: =F14*C14 | H14: =SUMIFS(Data_Balances!$G:$G,Data_Balances!$A:$A,EOMONTH($A14,-1),Data_Balances!$B:$B,$B$1,Data_Balances!$E:$E,">=30") | I14: =IFERROR(H14/SUMIFS(Data_Balances!$G:$G,Data_Balances!$A:$A,$A14,Data_Balances!$B:$B,$B$1),0) | J14: =SUMIFS(Data_Balances!$G:$G,Data_Balances!$A:$A,$A14,Data_Balances!$B:$B,$B$1,Data_Balances!$E:$E,">=90") | K14: =IFERROR(J14/SUMIFS(Data_Balances!$G:$G,Data_Balances!$A:$A,$A14,Data_Balances!$B:$B,$B$1),0) | L14: =SUMIFS(Data_Applications!$D:$D,Data_Applications!$A:$A,$A14,Data_Applications!$B:$B,$B$1) | M14: =SUMIFS(Data_Applications!$E:$E,Data_Applications!$A:$A,$A14,Data_Applications!$B:$B,$B$1) | N14: =IFERROR(M14/L14,0) | O14: =SUMIFS(Data_Balances!$F:$F,Data_Balances!$A:$A,$A14,Data_Balances!$B:$B,$B$1) | P14: =IFERROR(D14/O14,0)
A15: 45869 | B15: =SUMIFS(Data_Balances!$G:$G,Data_Balances!$A:$A,$A15,Data_Balances!$B:$B,$B$1,Data_Balances!$H:$H,"Personal Loans")+SUMIFS(Data_Balances!$G:$G,Data_Balances!$A:$A,$A15,Data_Balances!$B:$B,$B$1,Data_Balances!$C:$C,"CC*") | C15: =INDEX(Lookups!$F$3:$H$26,MATCH($A15,Lookups!$E$3:$E$26,0),MATCH($B$2,Lookups!$F$2:$H$2,0)) | D15: =B15*C15 | E15: =SUMIFS(Data_Originations!$D:$D,Data_Originations!$A:$A,$A15,Data_Originations!$B:$B,$B$1) | F15: =SUMIFS(Data_Originations!$E:$E,Data_Originations!$A:$A,$A15,Data_Originations!$B:$B,$B$1) | G15: =F15*C15 | H15: =SUMIFS(Data_Balances!$G:$G,Data_Balances!$A:$A,EOMONTH($A15,-1),Data_Balances!$B:$B,$B$1,Data_Balances!$E:$E,">=30") | I15: =IFERROR(H15/SUMIFS(Data_Balances!$G:$G,Data_Balances!$A:$A,$A15,Data_Balances!$B:$B,$B$1),0) | J15: =SUMIFS(Data_Balances!$G:$G,Data_Balances!$A:$A,$A15,Data_Balances!$B:$B,$B$1,Data_Balances!$E:$E,">=90") | K15: =IFERROR(J15/SUMIFS(Data_Balances!$G:$G,Data_Balances!$A:$A,$A15,Data_Balances!$B:$B,$B$1),0) | L15: =SUMIFS(Data_Applications!$D:$D,Data_Applications!$A:$A,$A15,Data_Applications!$B:$B,$B$1) | M15: =SUMIFS(Data_Applications!$E:$E,Data_Applications!$A:$A,$A15,Data_Applications!$B:$B,$B$1) | N15: =IFERROR(M15/L15,0) | O15: =SUMIFS(Data_Balances!$F:$F,Data_Balances!$A:$A,$A15,Data_Balances!$B:$B,$B$1) | P15: =IFERROR(D15/O15,0)
A16: 45900 | B16: =SUMIFS(Data_Balances!$G:$G,Data_Balances!$A:$A,$A16,Data_Balances!$B:$B,$B$1,Data_Balances!$H:$H,"Personal Loans")+SUMIFS(Data_Balances!$G:$G,Data_Balances!$A:$A,$A16,Data_Balances!$B:$B,$B$1,Data_Balances!$C:$C,"CC*") | C16: =INDEX(Lookups!$F$3:$H$26,MATCH($A16,Lookups!$E$3:$E$26,0),MATCH($B$2,Lookups!$F$2:$H$2,0)) | D16: =B16*C16 | E16: =SUMIFS(Data_Originations!$D:$D,Data_Originations!$A:$A,$A16,Data_Originations!$B:$B,$B$1) | F16: =SUMIFS(Data_Originations!$E:$E,Data_Originations!$A:$A,$A16,Data_Originations!$B:$B,$B$1) | G16: =F16*C16 | H16: =SUMIFS(Data_Balances!$G:$G,Data_Balances!$A:$A,EOMONTH($A16,-1),Data_Balances!$B:$B,$B$1,Data_Balances!$E:$E,">=30") | I16: =IFERROR(H16/SUMIFS(Data_Balances!$G:$G,Data_Balances!$A:$A,$A16,Data_Balances!$B:$B,$B$1),0) | J16: =SUMIFS(Data_Balances!$G:$G,Data_Balances!$A:$A,$A16,Data_Balances!$B:$B,$B$1,Data_Balances!$E:$E,">=90") | K16: =IFERROR(J16/SUMIFS(Data_Balances!$G:$G,Data_Balances!$A:$A,$A16,Data_Balances!$B:$B,$B$1),0) | L16: =SUMIFS(Data_Applications!$D:$D,Data_Applications!$A:$A,$A16,Data_Applications!$B:$B,$B$1) | M16: =SUMIFS(Data_Applications!$E:$E,Data_Applications!$A:$A,$A16,Data_Applications!$B:$B,$B$1) | N16: =IFERROR(M16/L16,0) | O16: =SUMIFS(Data_Balances!$F:$F,Data_Balances!$A:$A,$A16,Data_Balances!$B:$B,$B$1) | P16: =IFERROR(D16/O16,0)
... A28: 46265 | B28: =SUMIFS(Data_Balances!$G:$G,Data_Balances!$A:$A,$A28,Data_Balances!$B:$B,$B$1,Data_Balances!$H:$H,"Personal Loans")+SUMIFS(Data_Balances!$G:$G,Data_Balances!$A:$A,$A28,Data_Balances!$B:$B,$B$1,Data_Balances!$C:$C,"CC*") | C28: =INDEX(Lookups!$F$3:$H$26,MATCH($A28,Lookups!$E$3:$E$26,0),MATCH($B$2,Lookups!$F$2:$H$2,0)) | D28: =B28*C28 | E28: =SUMIFS(Data_Originations!$D:$D,Data_Originations!$A:$A,$A28,Data_Originations!$B:$B,$B$1) | F28: =SUMIFS(Data_Originations!$E:$E,Data_Originations!$A:$A,$A28,Data_Originations!$B:$B,$B$1) | G28: =F28*C28 | H28: =SUMIFS(Data_Balances!$G:$G,Data_Balances!$A:$A,EOMONTH($A28,-1),Data_Balances!$B:$B,$B$1,Data_Balances!$E:$E,">=30") | I28: =IFERROR(H28/SUMIFS(Data_Balances!$G:$G,Data_Balances!$A:$A,$A28,Data_Balances!$B:$B,$B$1),0) | J28: =SUMIFS(Data_Balances!$G:$G,Data_Balances!$A:$A,$A28,Data_Balances!$B:$B,$B$1,Data_Balances!$E:$E,">=90") | K28: =IFERROR(J28/SUMIFS(Data_Balances!$G:$G,Data_Balances!$A:$A,$A28,Data_Balances!$B:$B,$B$1),0) | L28: =SUMIFS(Data_Applications!$D:$D,Data_Applications!$A:$A,$A28,Data_Applications!$B:$B,$B$1) | M28: =SUMIFS(Data_Applications!$E:$E,Data_Applications!$A:$A,$A28,Data_Applications!$B:$B,$B$1) | N28: =IFERROR(M28/L28,0) | O28: =SUMIFS(Data_Balances!$F:$F,Data_Balances!$A:$A,$A28,Data_Balances!$B:$B,$B$1) | P28: =IFERROR(D28/O28,0)

Sheet RO
A1: Country | B1: RO | C1: Romania
A2: Currency | B2: RON
A4: Month end | B4: Portfolio balance (local) | C4: FX rate to EUR | D4: Portfolio balance (EUR) | E4: New accounts | F4: New originations (local) | G4: New originations (EUR) | H4: Balance 30+ DPD (local) | I4: 30+ DPD rate | J4: Balance 90+ DPD (local) | K4: 90+ DPD rate | L4: Applications received | M4: Applications approved | N4: Approval rate | O4: Active accounts | P4: Avg balance per customer (EUR)
A5: 45565 | B5: =SUMIFS(Data_Balances!$G:$G,Data_Balances!$A:$A,$A5,Data_Balances!$B:$B,$B$1,Data_Balances!$H:$H,"Personal Loans")+SUMIFS(Data_Balances!$G:$G,Data_Balances!$A:$A,$A5,Data_Balances!$B:$B,$B$1,Data_Balances!$C:$C,"CC*") | C5: =INDEX(Lookups!$F$3:$H$26,MATCH($A5,Lookups!$E$3:$E$26,0),MATCH($B$2,Lookups!$F$2:$H$2,0)) | D5: =B5*0.2012 | E5: =SUMIFS(Data_Originations!$D:$D,Data_Originations!$A:$A,$A5,Data_Originations!$B:$B,$B$1) | F5: =SUMIFS(Data_Originations!$E:$E,Data_Originations!$A:$A,$A5,Data_Originations!$B:$B,$B$1) | G5: =F5*0.2012 | H5: =SUMIFS(Data_Balances!$G:$G,Data_Balances!$A:$A,EOMONTH($A5,-1),Data_Balances!$B:$B,$B$1,Data_Balances!$E:$E,">=30") | I5: =IFERROR(H5/SUMIFS(Data_Balances!$G:$G,Data_Balances!$A:$A,$A5,Data_Balances!$B:$B,$B$1),0) | J5: =SUMIFS(Data_Balances!$G:$G,Data_Balances!$A:$A,$A5,Data_Balances!$B:$B,$B$1,Data_Balances!$E:$E,">=90") | K5: =IFERROR(J5/SUMIFS(Data_Balances!$G:$G,Data_Balances!$A:$A,$A5,Data_Balances!$B:$B,$B$1),0) | L5: =SUMIFS(Data_Applications!$D:$D,Data_Applications!$A:$A,$A5,Data_Applications!$B:$B,$B$1) | M5: =SUMIFS(Data_Applications!$E:$E,Data_Applications!$A:$A,$A5,Data_Applications!$B:$B,$B$1) | N5: =IFERROR(M5/L5,0) | O5: =SUMIFS(Data_Balances!$F:$F,Data_Balances!$A:$A,$A5,Data_Balances!$B:$B,$B$1) | P5: =IFERROR(D5/O5,0)
A6: 45596 | B6: =SUMIFS(Data_Balances!$G:$G,Data_Balances!$A:$A,$A6,Data_Balances!$B:$B,$B$1,Data_Balances!$H:$H,"Personal Loans")+SUMIFS(Data_Balances!$G:$G,Data_Balances!$A:$A,$A6,Data_Balances!$B:$B,$B$1,Data_Balances!$C:$C,"CC*") | C6: =INDEX(Lookups!$F$3:$H$26,MATCH($A6,Lookups!$E$3:$E$26,0),MATCH($B$2,Lookups!$F$2:$H$2,0)) | D6: =B6*0.2012 | E6: =SUMIFS(Data_Originations!$D:$D,Data_Originations!$A:$A,$A6,Data_Originations!$B:$B,$B$1) | F6: =SUMIFS(Data_Originations!$E:$E,Data_Originations!$A:$A,$A6,Data_Originations!$B:$B,$B$1) | G6: =F6*0.2012 | H6: =SUMIFS(Data_Balances!$G:$G,Data_Balances!$A:$A,EOMONTH($A6,-1),Data_Balances!$B:$B,$B$1,Data_Balances!$E:$E,">=30") | I6: =IFERROR(H6/SUMIFS(Data_Balances!$G:$G,Data_Balances!$A:$A,$A6,Data_Balances!$B:$B,$B$1),0) | J6: =SUMIFS(Data_Balances!$G:$G,Data_Balances!$A:$A,$A6,Data_Balances!$B:$B,$B$1,Data_Balances!$E:$E,">=90") | K6: =IFERROR(J6/SUMIFS(Data_Balances!$G:$G,Data_Balances!$A:$A,$A6,Data_Balances!$B:$B,$B$1),0) | L6: =SUMIFS(Data_Applications!$D:$D,Data_Applications!$A:$A,$A6,Data_Applications!$B:$B,$B$1) | M6: =SUMIFS(Data_Applications!$E:$E,Data_Applications!$A:$A,$A6,Data_Applications!$B:$B,$B$1) | N6: =IFERROR(M6/L6,0) | O6: =SUMIFS(Data_Balances!$F:$F,Data_Balances!$A:$A,$A6,Data_Balances!$B:$B,$B$1) | P6: =IFERROR(D6/O6,0)
A7: 45626 | B7: =SUMIFS(Data_Balances!$G:$G,Data_Balances!$A:$A,$A7,Data_Balances!$B:$B,$B$1,Data_Balances!$H:$H,"Personal Loans")+SUMIFS(Data_Balances!$G:$G,Data_Balances!$A:$A,$A7,Data_Balances!$B:$B,$B$1,Data_Balances!$C:$C,"CC*") | C7: =INDEX(Lookups!$F$3:$H$26,MATCH($A7,Lookups!$E$3:$E$26,0),MATCH($B$2,Lookups!$F$2:$H$2,0)) | D7: =B7*0.2012 | E7: =SUMIFS(Data_Originations!$D:$D,Data_Originations!$A:$A,$A7,Data_Originations!$B:$B,$B$1) | F7: =SUMIFS(Data_Originations!$E:$E,Data_Originations!$A:$A,$A7,Data_Originations!$B:$B,$B$1) | G7: =F7*0.2012 | H7: =SUMIFS(Data_Balances!$G:$G,Data_Balances!$A:$A,EOMONTH($A7,-1),Data_Balances!$B:$B,$B$1,Data_Balances!$E:$E,">=30") | I7: =IFERROR(H7/SUMIFS(Data_Balances!$G:$G,Data_Balances!$A:$A,$A7,Data_Balances!$B:$B,$B$1),0) | J7: =SUMIFS(Data_Balances!$G:$G,Data_Balances!$A:$A,$A7,Data_Balances!$B:$B,$B$1,Data_Balances!$E:$E,">=90") | K7: =IFERROR(J7/SUMIFS(Data_Balances!$G:$G,Data_Balances!$A:$A,$A7,Data_Balances!$B:$B,$B$1),0) | L7: =SUMIFS(Data_Applications!$D:$D,Data_Applications!$A:$A,$A7,Data_Applications!$B:$B,$B$1) | M7: =SUMIFS(Data_Applications!$E:$E,Data_Applications!$A:$A,$A7,Data_Applications!$B:$B,$B$1) | N7: =IFERROR(M7/L7,0) | O7: =SUMIFS(Data_Balances!$F:$F,Data_Balances!$A:$A,$A7,Data_Balances!$B:$B,$B$1) | P7: =IFERROR(D7/O7,0)
A8: 45657 | B8: =SUMIFS(Data_Balances!$G:$G,Data_Balances!$A:$A,$A8,Data_Balances!$B:$B,$B$1,Data_Balances!$H:$H,"Personal Loans")+SUMIFS(Data_Balances!$G:$G,Data_Balances!$A:$A,$A8,Data_Balances!$B:$B,$B$1,Data_Balances!$C:$C,"CC*") | C8: =INDEX(Lookups!$F$3:$H$26,MATCH($A8,Lookups!$E$3:$E$26,0),MATCH($B$2,Lookups!$F$2:$H$2,0)) | D8: =B8*0.2012 | E8: =SUMIFS(Data_Originations!$D:$D,Data_Originations!$A:$A,$A8,Data_Originations!$B:$B,$B$1) | F8: =SUMIFS(Data_Originations!$E:$E,Data_Originations!$A:$A,$A8,Data_Originations!$B:$B,$B$1) | G8: =F8*0.2012 | H8: =SUMIFS(Data_Balances!$G:$G,Data_Balances!$A:$A,EOMONTH($A8,-1),Data_Balances!$B:$B,$B$1,Data_Balances!$E:$E,">=30") | I8: =IFERROR(H8/SUMIFS(Data_Balances!$G:$G,Data_Balances!$A:$A,$A8,Data_Balances!$B:$B,$B$1),0) | J8: =SUMIFS(Data_Balances!$G:$G,Data_Balances!$A:$A,$A8,Data_Balances!$B:$B,$B$1,Data_Balances!$E:$E,">=90") | K8: =IFERROR(J8/SUMIFS(Data_Balances!$G:$G,Data_Balances!$A:$A,$A8,Data_Balances!$B:$B,$B$1),0) | L8: =SUMIFS(Data_Applications!$D:$D,Data_Applications!$A:$A,$A8,Data_Applications!$B:$B,$B$1) | M8: =SUMIFS(Data_Applications!$E:$E,Data_Applications!$A:$A,$A8,Data_Applications!$B:$B,$B$1) | N8: =IFERROR(M8/L8,0) | O8: =SUMIFS(Data_Balances!$F:$F,Data_Balances!$A:$A,$A8,Data_Balances!$B:$B,$B$1) | P8: =IFERROR(D8/O8,0)
A9: 45688 | B9: =SUMIFS(Data_Balances!$G:$G,Data_Balances!$A:$A,$A9,Data_Balances!$B:$B,$B$1,Data_Balances!$H:$H,"Personal Loans")+SUMIFS(Data_Balances!$G:$G,Data_Balances!$A:$A,$A9,Data_Balances!$B:$B,$B$1,Data_Balances!$C:$C,"CC*") | C9: =INDEX(Lookups!$F$3:$H$26,MATCH($A9,Lookups!$E$3:$E$26,0),MATCH($B$2,Lookups!$F$2:$H$2,0)) | D9: =B9*0.2012 | E9: =SUMIFS(Data_Originations!$D:$D,Data_Originations!$A:$A,$A9,Data_Originations!$B:$B,$B$1) | F9: =SUMIFS(Data_Originations!$E:$E,Data_Originations!$A:$A,$A9,Data_Originations!$B:$B,$B$1) | G9: =F9*0.2012 | H9: =SUMIFS(Data_Balances!$G:$G,Data_Balances!$A:$A,EOMONTH($A9,-1),Data_Balances!$B:$B,$B$1,Data_Balances!$E:$E,">=30") | I9: =IFERROR(H9/SUMIFS(Data_Balances!$G:$G,Data_Balances!$A:$A,$A9,Data_Balances!$B:$B,$B$1),0) | J9: =SUMIFS(Data_Balances!$G:$G,Data_Balances!$A:$A,$A9,Data_Balances!$B:$B,$B$1,Data_Balances!$E:$E,">=90") | K9: =IFERROR(J9/SUMIFS(Data_Balances!$G:$G,Data_Balances!$A:$A,$A9,Data_Balances!$B:$B,$B$1),0) | L9: =SUMIFS(Data_Applications!$D:$D,Data_Applications!$A:$A,$A9,Data_Applications!$B:$B,$B$1) | M9: =SUMIFS(Data_Applications!$E:$E,Data_Applications!$A:$A,$A9,Data_Applications!$B:$B,$B$1) | N9: =IFERROR(M9/L9,0) | O9: =SUMIFS(Data_Balances!$F:$F,Data_Balances!$A:$A,$A9,Data_Balances!$B:$B,$B$1) | P9: =IFERROR(D9/O9,0)
A10: 45716 | B10: =SUMIFS(Data_Balances!$G:$G,Data_Balances!$A:$A,$A10,Data_Balances!$B:$B,$B$1,Data_Balances!$H:$H,"Personal Loans")+SUMIFS(Data_Balances!$G:$G,Data_Balances!$A:$A,$A10,Data_Balances!$B:$B,$B$1,Data_Balances!$C:$C,"CC*") | C10: =INDEX(Lookups!$F$3:$H$26,MATCH($A10,Lookups!$E$3:$E$26,0),MATCH($B$2,Lookups!$F$2:$H$2,0)) | D10: =B10*0.2012 | E10: =SUMIFS(Data_Originations!$D:$D,Data_Originations!$A:$A,$A10,Data_Originations!$B:$B,$B$1) | F10: =SUMIFS(Data_Originations!$E:$E,Data_Originations!$A:$A,$A10,Data_Originations!$B:$B,$B$1) | G10: =F10*0.2012 | H10: =SUMIFS(Data_Balances!$G:$G,Data_Balances!$A:$A,EOMONTH($A10,-1),Data_Balances!$B:$B,$B$1,Data_Balances!$E:$E,">=30") | I10: =IFERROR(H10/SUMIFS(Data_Balances!$G:$G,Data_Balances!$A:$A,$A10,Data_Balances!$B:$B,$B$1),0) | J10: =SUMIFS(Data_Balances!$G:$G,Data_Balances!$A:$A,$A10,Data_Balances!$B:$B,$B$1,Data_Balances!$E:$E,">=90") | K10: =IFERROR(J10/SUMIFS(Data_Balances!$G:$G,Data_Balances!$A:$A,$A10,Data_Balances!$B:$B,$B$1),0) | L10: =SUMIFS(Data_Applications!$D:$D,Data_Applications!$A:$A,$A10,Data_Applications!$B:$B,$B$1) | M10: =SUMIFS(Data_Applications!$E:$E,Data_Applications!$A:$A,$A10,Data_Applications!$B:$B,$B$1) | N10: =IFERROR(M10/L10,0) | O10: =SUMIFS(Data_Balances!$F:$F,Data_Balances!$A:$A,$A10,Data_Balances!$B:$B,$B$1) | P10: =IFERROR(D10/O10,0)
A11: 45747 | B11: =SUMIFS(Data_Balances!$G:$G,Data_Balances!$A:$A,$A11,Data_Balances!$B:$B,$B$1,Data_Balances!$H:$H,"Personal Loans")+SUMIFS(Data_Balances!$G:$G,Data_Balances!$A:$A,$A11,Data_Balances!$B:$B,$B$1,Data_Balances!$C:$C,"CC*") | C11: =INDEX(Lookups!$F$3:$H$26,MATCH($A11,Lookups!$E$3:$E$26,0),MATCH($B$2,Lookups!$F$2:$H$2,0)) | D11: =B11*0.2012 | E11: =SUMIFS(Data_Originations!$D:$D,Data_Originations!$A:$A,$A11,Data_Originations!$B:$B,$B$1) | F11: =SUMIFS(Data_Originations!$E:$E,Data_Originations!$A:$A,$A11,Data_Originations!$B:$B,$B$1) | G11: =F11*0.2012 | H11: =SUMIFS(Data_Balances!$G:$G,Data_Balances!$A:$A,EOMONTH($A11,-1),Data_Balances!$B:$B,$B$1,Data_Balances!$E:$E,">=30") | I11: =IFERROR(H11/SUMIFS(Data_Balances!$G:$G,Data_Balances!$A:$A,$A11,Data_Balances!$B:$B,$B$1),0) | J11: =SUMIFS(Data_Balances!$G:$G,Data_Balances!$A:$A,$A11,Data_Balances!$B:$B,$B$1,Data_Balances!$E:$E,">=90") | K11: =IFERROR(J11/SUMIFS(Data_Balances!$G:$G,Data_Balances!$A:$A,$A11,Data_Balances!$B:$B,$B$1),0) | L11: =SUMIFS(Data_Applications!$D:$D,Data_Applications!$A:$A,$A11,Data_Applications!$B:$B,$B$1) | M11: =SUMIFS(Data_Applications!$E:$E,Data_Applications!$A:$A,$A11,Data_Applications!$B:$B,$B$1) | N11: =IFERROR(M11/L11,0) | O11: =SUMIFS(Data_Balances!$F:$F,Data_Balances!$A:$A,$A11,Data_Balances!$B:$B,$B$1) | P11: =IFERROR(D11/O11,0)
A12: 45777 | B12: =SUMIFS(Data_Balances!$G:$G,Data_Balances!$A:$A,$A12,Data_Balances!$B:$B,$B$1,Data_Balances!$H:$H,"Personal Loans")+SUMIFS(Data_Balances!$G:$G,Data_Balances!$A:$A,$A12,Data_Balances!$B:$B,$B$1,Data_Balances!$C:$C,"CC*") | C12: =INDEX(Lookups!$F$3:$H$26,MATCH($A12,Lookups!$E$3:$E$26,0),MATCH($B$2,Lookups!$F$2:$H$2,0)) | D12: =B12*0.2012 | E12: =SUMIFS(Data_Originations!$D:$D,Data_Originations!$A:$A,$A12,Data_Originations!$B:$B,$B$1) | F12: =SUMIFS(Data_Originations!$E:$E,Data_Originations!$A:$A,$A12,Data_Originations!$B:$B,$B$1) | G12: =F12*0.2012 | H12: =SUMIFS(Data_Balances!$G:$G,Data_Balances!$A:$A,EOMONTH($A12,-1),Data_Balances!$B:$B,$B$1,Data_Balances!$E:$E,">=30") | I12: =IFERROR(H12/SUMIFS(Data_Balances!$G:$G,Data_Balances!$A:$A,$A12,Data_Balances!$B:$B,$B$1),0) | J12: =SUMIFS(Data_Balances!$G:$G,Data_Balances!$A:$A,$A12,Data_Balances!$B:$B,$B$1,Data_Balances!$E:$E,">=90") | K12: =IFERROR(J12/SUMIFS(Data_Balances!$G:$G,Data_Balances!$A:$A,$A12,Data_Balances!$B:$B,$B$1),0) | L12: =SUMIFS(Data_Applications!$D:$D,Data_Applications!$A:$A,$A12,Data_Applications!$B:$B,$B$1) | M12: =SUMIFS(Data_Applications!$E:$E,Data_Applications!$A:$A,$A12,Data_Applications!$B:$B,$B$1) | N12: =IFERROR(M12/L12,0) | O12: =SUMIFS(Data_Balances!$F:$F,Data_Balances!$A:$A,$A12,Data_Balances!$B:$B,$B$1) | P12: =IFERROR(D12/O12,0)
A13: 45808 | B13: =SUMIFS(Data_Balances!$G:$G,Data_Balances!$A:$A,$A13,Data_Balances!$B:$B,$B$1,Data_Balances!$H:$H,"Personal Loans")+SUMIFS(Data_Balances!$G:$G,Data_Balances!$A:$A,$A13,Data_Balances!$B:$B,$B$1,Data_Balances!$C:$C,"CC*") | C13: =INDEX(Lookups!$F$3:$H$26,MATCH($A13,Lookups!$E$3:$E$26,0),MATCH($B$2,Lookups!$F$2:$H$2,0)) | D13: =B13*0.2012 | E13: =SUMIFS(Data_Originations!$D:$D,Data_Originations!$A:$A,$A13,Data_Originations!$B:$B,$B$1) | F13: =SUMIFS(Data_Originations!$E:$E,Data_Originations!$A:$A,$A13,Data_Originations!$B:$B,$B$1) | G13: =F13*0.2012 | H13: =SUMIFS(Data_Balances!$G:$G,Data_Balances!$A:$A,EOMONTH($A13,-1),Data_Balances!$B:$B,$B$1,Data_Balances!$E:$E,">=30") | I13: =IFERROR(H13/SUMIFS(Data_Balances!$G:$G,Data_Balances!$A:$A,$A13,Data_Balances!$B:$B,$B$1),0) | J13: =SUMIFS(Data_Balances!$G:$G,Data_Balances!$A:$A,$A13,Data_Balances!$B:$B,$B$1,Data_Balances!$E:$E,">=90") | K13: =IFERROR(J13/SUMIFS(Data_Balances!$G:$G,Data_Balances!$A:$A,$A13,Data_Balances!$B:$B,$B$1),0) | L13: =SUMIFS(Data_Applications!$D:$D,Data_Applications!$A:$A,$A13,Data_Applications!$B:$B,$B$1) | M13: =SUMIFS(Data_Applications!$E:$E,Data_Applications!$A:$A,$A13,Data_Applications!$B:$B,$B$1) | N13: =IFERROR(M13/L13,0) | O13: =SUMIFS(Data_Balances!$F:$F,Data_Balances!$A:$A,$A13,Data_Balances!$B:$B,$B$1) | P13: =IFERROR(D13/O13,0)
A14: 45838 | B14: =SUMIFS(Data_Balances!$G:$G,Data_Balances!$A:$A,$A14,Data_Balances!$B:$B,$B$1,Data_Balances!$H:$H,"Personal Loans")+SUMIFS(Data_Balances!$G:$G,Data_Balances!$A:$A,$A14,Data_Balances!$B:$B,$B$1,Data_Balances!$C:$C,"CC*") | C14: =INDEX(Lookups!$F$3:$H$26,MATCH($A14,Lookups!$E$3:$E$26,0),MATCH($B$2,Lookups!$F$2:$H$2,0)) | D14: =B14*0.2012 | E14: =SUMIFS(Data_Originations!$D:$D,Data_Originations!$A:$A,$A14,Data_Originations!$B:$B,$B$1) | F14: =SUMIFS(Data_Originations!$E:$E,Data_Originations!$A:$A,$A14,Data_Originations!$B:$B,$B$1) | G14: =F14*0.2012 | H14: =SUMIFS(Data_Balances!$G:$G,Data_Balances!$A:$A,EOMONTH($A14,-1),Data_Balances!$B:$B,$B$1,Data_Balances!$E:$E,">=30") | I14: =IFERROR(H14/SUMIFS(Data_Balances!$G:$G,Data_Balances!$A:$A,$A14,Data_Balances!$B:$B,$B$1),0) | J14: =SUMIFS(Data_Balances!$G:$G,Data_Balances!$A:$A,$A14,Data_Balances!$B:$B,$B$1,Data_Balances!$E:$E,">=90") | K14: =IFERROR(J14/SUMIFS(Data_Balances!$G:$G,Data_Balances!$A:$A,$A14,Data_Balances!$B:$B,$B$1),0) | L14: =SUMIFS(Data_Applications!$D:$D,Data_Applications!$A:$A,$A14,Data_Applications!$B:$B,$B$1) | M14: =SUMIFS(Data_Applications!$E:$E,Data_Applications!$A:$A,$A14,Data_Applications!$B:$B,$B$1) | N14: =IFERROR(M14/L14,0) | O14: =SUMIFS(Data_Balances!$F:$F,Data_Balances!$A:$A,$A14,Data_Balances!$B:$B,$B$1) | P14: =IFERROR(D14/O14,0)
A15: 45869 | B15: =SUMIFS(Data_Balances!$G:$G,Data_Balances!$A:$A,$A15,Data_Balances!$B:$B,$B$1,Data_Balances!$H:$H,"Personal Loans")+SUMIFS(Data_Balances!$G:$G,Data_Balances!$A:$A,$A15,Data_Balances!$B:$B,$B$1,Data_Balances!$C:$C,"CC*") | C15: =INDEX(Lookups!$F$3:$H$26,MATCH($A15,Lookups!$E$3:$E$26,0),MATCH($B$2,Lookups!$F$2:$H$2,0)) | D15: =B15*0.2012 | E15: =SUMIFS(Data_Originations!$D:$D,Data_Originations!$A:$A,$A15,Data_Originations!$B:$B,$B$1) | F15: =SUMIFS(Data_Originations!$E:$E,Data_Originations!$A:$A,$A15,Data_Originations!$B:$B,$B$1) | G15: =F15*0.2012 | H15: =SUMIFS(Data_Balances!$G:$G,Data_Balances!$A:$A,EOMONTH($A15,-1),Data_Balances!$B:$B,$B$1,Data_Balances!$E:$E,">=30") | I15: =IFERROR(H15/SUMIFS(Data_Balances!$G:$G,Data_Balances!$A:$A,$A15,Data_Balances!$B:$B,$B$1),0) | J15: =SUMIFS(Data_Balances!$G:$G,Data_Balances!$A:$A,$A15,Data_Balances!$B:$B,$B$1,Data_Balances!$E:$E,">=90") | K15: =IFERROR(J15/SUMIFS(Data_Balances!$G:$G,Data_Balances!$A:$A,$A15,Data_Balances!$B:$B,$B$1),0) | L15: =SUMIFS(Data_Applications!$D:$D,Data_Applications!$A:$A,$A15,Data_Applications!$B:$B,$B$1) | M15: =SUMIFS(Data_Applications!$E:$E,Data_Applications!$A:$A,$A15,Data_Applications!$B:$B,$B$1) | N15: =IFERROR(M15/L15,0) | O15: =SUMIFS(Data_Balances!$F:$F,Data_Balances!$A:$A,$A15,Data_Balances!$B:$B,$B$1) | P15: =IFERROR(D15/O15,0)
A16: 45900 | B16: =SUMIFS(Data_Balances!$G:$G,Data_Balances!$A:$A,$A16,Data_Balances!$B:$B,$B$1,Data_Balances!$H:$H,"Personal Loans")+SUMIFS(Data_Balances!$G:$G,Data_Balances!$A:$A,$A16,Data_Balances!$B:$B,$B$1,Data_Balances!$C:$C,"CC*") | C16: =INDEX(Lookups!$F$3:$H$26,MATCH($A16,Lookups!$E$3:$E$26,0),MATCH($B$2,Lookups!$F$2:$H$2,0)) | D16: =B16*0.2012 | E16: =SUMIFS(Data_Originations!$D:$D,Data_Originations!$A:$A,$A16,Data_Originations!$B:$B,$B$1) | F16: =SUMIFS(Data_Originations!$E:$E,Data_Originations!$A:$A,$A16,Data_Originations!$B:$B,$B$1) | G16: =F16*0.2012 | H16: =SUMIFS(Data_Balances!$G:$G,Data_Balances!$A:$A,EOMONTH($A16,-1),Data_Balances!$B:$B,$B$1,Data_Balances!$E:$E,">=30") | I16: =IFERROR(H16/SUMIFS(Data_Balances!$G:$G,Data_Balances!$A:$A,$A16,Data_Balances!$B:$B,$B$1),0) | J16: =SUMIFS(Data_Balances!$G:$G,Data_Balances!$A:$A,$A16,Data_Balances!$B:$B,$B$1,Data_Balances!$E:$E,">=90") | K16: =IFERROR(J16/SUMIFS(Data_Balances!$G:$G,Data_Balances!$A:$A,$A16,Data_Balances!$B:$B,$B$1),0) | L16: =SUMIFS(Data_Applications!$D:$D,Data_Applications!$A:$A,$A16,Data_Applications!$B:$B,$B$1) | M16: =SUMIFS(Data_Applications!$E:$E,Data_Applications!$A:$A,$A16,Data_Applications!$B:$B,$B$1) | N16: =IFERROR(M16/L16,0) | O16: =SUMIFS(Data_Balances!$F:$F,Data_Balances!$A:$A,$A16,Data_Balances!$B:$B,$B$1) | P16: =IFERROR(D16/O16,0)
... A28: 46265 | B28: =SUMIFS(Data_Balances!$G:$G,Data_Balances!$A:$A,$A28,Data_Balances!$B:$B,$B$1,Data_Balances!$H:$H,"Personal Loans")+SUMIFS(Data_Balances!$G:$G,Data_Balances!$A:$A,$A28,Data_Balances!$B:$B,$B$1,Data_Balances!$C:$C,"CC*") | C28: =INDEX(Lookups!$F$3:$H$26,MATCH($A28,Lookups!$E$3:$E$26,0),MATCH($B$2,Lookups!$F$2:$H$2,0)) | D28: =B28*0.2012 | E28: =SUMIFS(Data_Originations!$D:$D,Data_Originations!$A:$A,$A28,Data_Originations!$B:$B,$B$1) | F28: =SUMIFS(Data_Originations!$E:$E,Data_Originations!$A:$A,$A28,Data_Originations!$B:$B,$B$1) | G28: =F28*0.2012 | H28: =SUMIFS(Data_Balances!$G:$G,Data_Balances!$A:$A,EOMONTH($A28,-1),Data_Balances!$B:$B,$B$1,Data_Balances!$E:$E,">=30") | I28: =IFERROR(H28/SUMIFS(Data_Balances!$G:$G,Data_Balances!$A:$A,$A28,Data_Balances!$B:$B,$B$1),0) | J28: =SUMIFS(Data_Balances!$G:$G,Data_Balances!$A:$A,$A28,Data_Balances!$B:$B,$B$1,Data_Balances!$E:$E,">=90") | K28: =IFERROR(J28/SUMIFS(Data_Balances!$G:$G,Data_Balances!$A:$A,$A28,Data_Balances!$B:$B,$B$1),0) | L28: =SUMIFS(Data_Applications!$D:$D,Data_Applications!$A:$A,$A28,Data_Applications!$B:$B,$B$1) | M28: =SUMIFS(Data_Applications!$E:$E,Data_Applications!$A:$A,$A28,Data_Applications!$B:$B,$B$1) | N28: =IFERROR(M28/L28,0) | O28: =SUMIFS(Data_Balances!$F:$F,Data_Balances!$A:$A,$A28,Data_Balances!$B:$B,$B$1) | P28: =IFERROR(D28/O28,0)

Sheet Data_Balances
A1: snapshot_date | B1: country_code | C1: product_code | D1: dpd_bucket | E1: dpd_min | F1: accounts | G1: balance_local | H1: Product line
A2: 45565 | B2: CZ | C2: CC_CLASSIC | D2: Current | E2: 0 | F2: 758 | G2: 11415391 | H2: =IFERROR(VLOOKUP(C2,Lookups!$A$3:$C$7,3,FALSE),"UNMAPPED")
A3: 45565 | B3: CZ | C3: CC_CLASSIC | D3: 1-29 | E3: 1 | F3: 9 | G3: 139848.17 | H3: =IFERROR(VLOOKUP(C3,Lookups!$A$3:$C$7,3,FALSE),"UNMAPPED")
A4: 45565 | B4: CZ | C4: CC_CLASSIC | D4: 30-59 | E4: 30 | F4: 5 | G4: 71288.99 | H4: =IFERROR(VLOOKUP(C4,Lookups!$A$3:$C$7,3,FALSE),"UNMAPPED")
A5: 45565 | B5: CZ | C5: CC_CLASSIC | D5: 60-89 | E5: 60 | F5: 6 | G5: 112568.94 | H5: =IFERROR(VLOOKUP(C5,Lookups!$A$3:$C$7,3,FALSE),"UNMAPPED")
A6: 45565 | B6: CZ | C6: CC_CLASSIC | D6: 90-179 | E6: 90 | F6: 10 | G6: 210834.46 | H6: =IFERROR(VLOOKUP(C6,Lookups!$A$3:$C$7,3,FALSE),"UNMAPPED")
A7: 45565 | B7: CZ | C7: CC_GOLD | D7: Current | E7: 0 | F7: 225 | G7: 12679561 | H7: =IFERROR(VLOOKUP(C7,Lookups!$A$3:$C$7,3,FALSE),"UNMAPPED")
A8: 45565 | B8: CZ | C8: CC_GOLD | D8: 1-29 | E8: 1 | F8: 3 | G8: 246683.69 | H8: =IFERROR(VLOOKUP(C8,Lookups!$A$3:$C$7,3,FALSE),"UNMAPPED")
A9: 45565 | B9: CZ | C9: CC_GOLD | D9: 90-179 | E9: 90 | F9: 2 | G9: 139867.14 | H9: =IFERROR(VLOOKUP(C9,Lookups!$A$3:$C$7,3,FALSE),"UNMAPPED")
